package hello.advanced.v3;


import hello.advanced.trace.TraceStatus;
import hello.advanced.trace.hellotrace.HelloTraceV2;
import hello.advanced.trace.logtrace.LogTrace;
import lombok.RequiredArgsConstructor;
import org.springframework.web.bind.annotation.GetMapping;
import org.springframework.web.bind.annotation.RestController;

@RestController
@RequiredArgsConstructor
public class OrderControllerV3 {

    private final OrderServiceV3 orderService;
    private final LogTrace trace;

    @GetMapping("/v3/request")
    public String request(String itemId) {
        TraceStatus status = null;
        try {
            status = trace.begin("OrderController.request()");
            orderService.orderItem(itemId);
            trace.end(status);
            return "ok";
        }catch (Exception e){
            trace.exception(status, e);
            throw e; // 예외를 다시 던져주는 이유는 위 코드인 trace.exception() 에서 예외를 잡아먹기 때문이다.
        }
    }
}
